<mujocoinclude>
    <body name="omx_left" pos="0 -0.4 0" euler="0 0 1.57">
        <!-- 로봇 베이스 및 기타 링크 정의 -->
        <geom quat="0.707107 0 0 0.707107" type="mesh" mesh="link1" name="omx_left/link1" contype="0" conaffinity="0"/>
        <body name="omx_left/link2" pos="0.012 0 0.017">
            <inertial pos="-0.000301849 0.000540437 0.0474335" quat="0.999915 0.000960074 0.0122201 -0.00449872" mass="0.0984068" diaginertia="3.4553e-05 3.26892e-05 1.88409e-05"/>
            <joint name="omx_left/joint1" pos="0 0 0" axis="0 0 1" range="-3.14159 3.14159"/>
            <geom pos="0 0 0.019" quat="1 0 0 0" type="mesh" mesh="link2"/>
            <body name="omx_left/link3" pos="0 0 0.0595">
                <inertial pos="0.0103084 0.000377434 0.101702" quat="0.71133 0.0466763 0.0513691 0.699423" mass="0.138509" diaginertia="0.000342915 0.000335932 5.49578e-05"/>
                <joint name="omx_left/joint2" pos="0 0 0" axis="0 1 0" range="-1.5 1.5"/>
                <geom type="mesh" mesh="link3"/>
                <body name="omx_left/link4" pos="0.024 0 0.128">
                    <inertial pos="0.0909096 0.000389298 0.000224133" quat="-0.00162881 0.706672 0.0026348 0.707535" mass="0.132746" diaginertia="0.000251551 0.000242311 3.06462e-05"/>
                    <joint name="omx_left/joint3" pos="0 0 0" axis="0 1 0" range="-1.5 1.4"/>
                    <geom type="mesh" mesh="link4"/>
                    <body name="omx_left/link5" pos="0.124 0 0">
                        <inertial pos="0.0442068 3.684e-07 0.00891422" quat="0.479052 0.479052 -0.520105 0.520105" mass="0.143276" diaginertia="9.3211e-05 8.07871e-05 7.59805e-05"/>
                        <joint name="omx_left/joint4" pos="0 0 0" axis="0 1 0" range="-1.7 1.97"/>
                        <geom type="mesh" mesh="link5"/>
                        <!-- 카메라를 link5에 직접 추가 (위치만 앞으로 조정) -->
                        <geom type="mesh" mesh="d405_solid" material="camera_black" pos="0.07 0 0.06" quat="0.7071 0 0.7071 0"/>
                        <camera name="left_wrist_cam" pos="0.07 0 0.06" mode="fixed" euler="0 1.57 0"
                                focal="1.93e-3 1.93e-3" resolution="1280 720" sensorsize="3896e-6 2140e-6"/>
                        <!-- 그리퍼 핑거 정의 -->
                        <body name="omx_left/gripper_left_link" pos="0.0817 0.021 0">
                            <inertial pos="0 0 0" mass="0.001" diaginertia="1e-06 1e-06 1e-06"/>
                            <joint name="omx_left/gripper_left_joint" pos="0 0 0" axis="0 1 0" type="slide" range="-0.01 0.019"/>
                            <geom type="mesh" mesh="gripper_left_palm"/>
                        </body>
                        <body name="omx_left/gripper_right_link" pos="0.0817 -0.021 0">
                            <inertial pos="0 0 0" mass="0.001" diaginertia="1e-06 1e-06 1e-06"/>
                            <joint name="omx_left/gripper_right_joint" pos="0 0 0" axis="0 -1 0" type="slide" range="-0.01 0.019"/>
                            <geom type="mesh" mesh="gripper_right_palm"/>
                        </body>
                        <!-- target -->
                        <body name="omx_left/end_effector_target" pos="0.14 0 0">
                            <inertial pos="0 0 0" mass="0.001" diaginertia="1e-06 1e-06 1e-06"/>
                            <geom type="box" size="0.005 0.005 0.005" rgba="1 0 0 1" contype="0" conaffinity="0"/>
                        </body>
                    </body>
                </body>
            </body>
        </body>
    </body>
</mujocoinclude>